<?xml version="1.0" encoding="UTF-8"?>
<!-- Generated by org.testng.reporters.JUnitReportReporter -->
<testsuite hostname="DS-7071BC9E7AC9" name="com.TestNG.Demo1.Priority" tests="4" failures="1" timestamp="9 Aug 2016 11:25:23 GMT" time="0.018" errors="2">
  <testcase name="enterTheText" time="0.004" classname="com.TestNG.Demo1.Priority">
    <failure type="java.lang.AssertionError" message="expected [ABC] but found [abc]">
      <![CDATA[java.lang.AssertionError: expected [ABC] but found [abc]
	at org.testng.Assert.fail(Assert.java:94)
	at org.testng.Assert.failNotEquals(Assert.java:513)
	at org.testng.Assert.assertEqualsImpl(Assert.java:135)
	at org.testng.Assert.assertEquals(Assert.java:116)
	at org.testng.Assert.assertEquals(Assert.java:190)
	at org.testng.Assert.assertEquals(Assert.java:200)
	at com.TestNG.Demo1.Priority.enterTheText(Priority.java:15)
	at sun.reflect.NativeMethodAccessorImpl.invoke0(Native Method)
	at sun.reflect.NativeMethodAccessorImpl.invoke(Unknown Source)
	at sun.reflect.DelegatingMethodAccessorImpl.invoke(Unknown Source)
	at java.lang.reflect.Method.invoke(Unknown Source)
	at org.testng.internal.MethodInvocationHelper.invokeMethod(MethodInvocationHelper.java:100)
	at org.testng.internal.Invoker.invokeMethod(Invoker.java:646)
	at org.testng.internal.Invoker.invokeTestMethod(Invoker.java:811)
	at org.testng.internal.Invoker.invokeTestMethods(Invoker.java:1129)
	at org.testng.internal.TestMethodWorker.invokeTestMethods(TestMethodWorker.java:129)
	at org.testng.internal.TestMethodWorker.run(TestMethodWorker.java:112)
	at org.testng.TestRunner.privateRun(TestRunner.java:746)
	at org.testng.TestRunner.run(TestRunner.java:600)
	at org.testng.SuiteRunner.runTest(SuiteRunner.java:366)
	at org.testng.SuiteRunner.runSequentially(SuiteRunner.java:361)
	at org.testng.SuiteRunner.privateRun(SuiteRunner.java:319)
	at org.testng.SuiteRunner.run(SuiteRunner.java:268)
	at org.testng.SuiteRunnerWorker.runSuite(SuiteRunnerWorker.java:52)
	at org.testng.SuiteRunnerWorker.run(SuiteRunnerWorker.java:86)
	at org.testng.TestNG.runSuitesSequentially(TestNG.java:1264)
	at org.testng.TestNG.runSuitesLocally(TestNG.java:1189)
	at org.testng.TestNG.runSuites(TestNG.java:1104)
	at org.testng.TestNG.run(TestNG.java:1076)
	at org.testng.remote.AbstractRemoteTestNG.run(AbstractRemoteTestNG.java:126)
	at org.testng.remote.RemoteTestNG.initAndRun(RemoteTestNG.java:152)
	at org.testng.remote.RemoteTestNG.main(RemoteTestNG.java:57)
]]>
    </failure>
  </testcase> <!-- enterTheText -->
  <testcase name="Logout" time="0.000" classname="com.TestNG.Demo1.Priority">
    <error type="java.lang.Throwable" message="Method Priority.Logout()[pri:0, instance:com.TestNG.Demo1.Priority@24a67] depends on not successfully finished methods">
      <![CDATA[java.lang.Throwable: Method Priority.Logout()[pri:0, instance:com.TestNG.Demo1.Priority@24a67] depends on not successfully finished methods
	at org.testng.internal.Invoker.invokeTestMethods(Invoker.java:1028)
	at org.testng.internal.TestMethodWorker.invokeTestMethods(TestMethodWorker.java:129)
	at org.testng.internal.TestMethodWorker.run(TestMethodWorker.java:112)
	at org.testng.TestRunner.privateRun(TestRunner.java:746)
	at org.testng.TestRunner.run(TestRunner.java:600)
	at org.testng.SuiteRunner.runTest(SuiteRunner.java:366)
	at org.testng.SuiteRunner.runSequentially(SuiteRunner.java:361)
	at org.testng.SuiteRunner.privateRun(SuiteRunner.java:319)
	at org.testng.SuiteRunner.run(SuiteRunner.java:268)
	at org.testng.SuiteRunnerWorker.runSuite(SuiteRunnerWorker.java:52)
	at org.testng.SuiteRunnerWorker.run(SuiteRunnerWorker.java:86)
	at org.testng.TestNG.runSuitesSequentially(TestNG.java:1264)
	at org.testng.TestNG.runSuitesLocally(TestNG.java:1189)
	at org.testng.TestNG.runSuites(TestNG.java:1104)
	at org.testng.TestNG.run(TestNG.java:1076)
	at org.testng.remote.AbstractRemoteTestNG.run(AbstractRemoteTestNG.java:126)
	at org.testng.remote.RemoteTestNG.initAndRun(RemoteTestNG.java:152)
	at org.testng.remote.RemoteTestNG.main(RemoteTestNG.java:57)
]]>
    </error>
  </testcase> <!-- Logout -->
  <testcase name="search" time="0.000" classname="com.TestNG.Demo1.Priority">
    <error type="java.lang.Throwable" message="Method Priority.search()[pri:0, instance:com.TestNG.Demo1.Priority@24a67] depends on not successfully finished methods">
      <![CDATA[java.lang.Throwable: Method Priority.search()[pri:0, instance:com.TestNG.Demo1.Priority@24a67] depends on not successfully finished methods
	at org.testng.internal.Invoker.invokeTestMethods(Invoker.java:1028)
	at org.testng.internal.TestMethodWorker.invokeTestMethods(TestMethodWorker.java:129)
	at org.testng.internal.TestMethodWorker.run(TestMethodWorker.java:112)
	at org.testng.TestRunner.privateRun(TestRunner.java:746)
	at org.testng.TestRunner.run(TestRunner.java:600)
	at org.testng.SuiteRunner.runTest(SuiteRunner.java:366)
	at org.testng.SuiteRunner.runSequentially(SuiteRunner.java:361)
	at org.testng.SuiteRunner.privateRun(SuiteRunner.java:319)
	at org.testng.SuiteRunner.run(SuiteRunner.java:268)
	at org.testng.SuiteRunnerWorker.runSuite(SuiteRunnerWorker.java:52)
	at org.testng.SuiteRunnerWorker.run(SuiteRunnerWorker.java:86)
	at org.testng.TestNG.runSuitesSequentially(TestNG.java:1264)
	at org.testng.TestNG.runSuitesLocally(TestNG.java:1189)
	at org.testng.TestNG.runSuites(TestNG.java:1104)
	at org.testng.TestNG.run(TestNG.java:1076)
	at org.testng.remote.AbstractRemoteTestNG.run(AbstractRemoteTestNG.java:126)
	at org.testng.remote.RemoteTestNG.initAndRun(RemoteTestNG.java:152)
	at org.testng.remote.RemoteTestNG.main(RemoteTestNG.java:57)
]]>
    </error>
  </testcase> <!-- search -->
  <testcase name="Login" time="0.014" classname="com.TestNG.Demo1.Priority"/>
</testsuite> <!-- com.TestNG.Demo1.Priority -->
